Workbook

Sheet Log Diário
A1: HOPI HARI · LOG DIÁRIO DE SEGUIDORES
A2: Preencha o total de cada rede por dia (colunas azuis). TOTAL, META e deltas calculam sozinhos. Correção aplicada em 13/06 (Instagram).
B3: TOTAL DE SEGUIDORES (preencher) | I3: NET DIÁRIO (calculado)
A4: Data | B4: Instagram | C4: TikTok | D4: Facebook | E4: YouTube | F4: LinkedIn | G4: TOTAL | H4: META (3M) | I4: Δ Instagram | J4: Δ TikTok | K4: Δ Facebook | L4: Δ YouTube | M4: Δ LinkedIn
A5: 46175 | B5: 1521064 | C5: 404326 | D5: 988295 | E5: 56858 | F5: 16824 | G5: =IF(COUNT(B5:F5)=0,"",SUM(B5:F5)) -> 2987367 | H5: 3000000 | I5: — | J5: — | K5: — | L5: — | M5: —
A6: 46176 | B6: 1521132 | C6: 404553 | D6: 986000 | E6: 57000 | F6: 17000 | G6: =IF(COUNT(B6:F6)=0,"",SUM(B6:F6)) -> 2985685 | H6: 3000000 | I6: =IF(OR(B6="",B5=""),"",B6-B5) -> 68 | J6: =IF(OR(C6="",C5=""),"",C6-C5) -> 227 | K6: =IF(OR(D6="",D5=""),"",D6-D5) -> -2295 | L6: =IF(OR(E6="",E5=""),"",E6-E5) -> 142 | M6: =IF(OR(F6="",F5=""),"",F6-F5) -> 176
A7: 46177 | B7: 1521866 | C7: 404700 | D7: 986000 | E7: 57000 | F7: 17000 | G7: =IF(COUNT(B7:F7)=0,"",SUM(B7:F7)) -> 2986566 | H7: 3000000 | I7: =IF(OR(B7="",B6=""),"",B7-B6) -> 734 | J7: =IF(OR(C7="",C6=""),"",C7-C6) -> 147 | K7: =IF(OR(D7="",D6=""),"",D7-D6) -> 0 | L7: =IF(OR(E7="",E6=""),"",E7-E6) -> 0 | M7: =IF(OR(F7="",F6=""),"",F7-F6) -> 0
A8: 46178 | B8: 1521866 | C8: 404700 | D8: 986000 | E8: 57000 | F8: 17000 | G8: =IF(COUNT(B8:F8)=0,"",SUM(B8:F8)) -> 2986566 | H8: 3000000 | I8: =IF(OR(B8="",B7=""),"",B8-B7) -> 0 | J8: =IF(OR(C8="",C7=""),"",C8-C7) -> 0 | K8: =IF(OR(D8="",D7=""),"",D8-D7) -> 0 | L8: =IF(OR(E8="",E7=""),"",E8-E7) -> 0 | M8: =IF(OR(F8="",F7=""),"",F8-F7) -> 0
A9: 46179 | B9: 1522351 | C9: 404800 | D9: 986000 | E9: 57000 | F9: 17000 | G9: =IF(COUNT(B9:F9)=0,"",SUM(B9:F9)) -> 2987151 | H9: 3000000 | I9: =IF(OR(B9="",B8=""),"",B9-B8) -> 485 | J9: =IF(OR(C9="",C8=""),"",C9-C8) -> 100 | K9: =IF(OR(D9="",D8=""),"",D9-D8) -> 0 | L9: =IF(OR(E9="",E8=""),"",E9-E8) -> 0 | M9: =IF(OR(F9="",F8=""),"",F9-F8) -> 0
A10: 46180 | B10: 1522845 | C10: 404800 | D10: 986000 | E10: 57000 | F10: 17000 | G10: =IF(COUNT(B10:F10)=0,"",SUM(B10:F10)) -> 2987645 | H10: 3000000 | I10: =IF(OR(B10="",B9=""),"",B10-B9) -> 494 | J10: =IF(OR(C10="",C9=""),"",C10-C9) -> 0 | K10: =IF(OR(D10="",D9=""),"",D10-D9) -> 0 | L10: =IF(OR(E10="",E9=""),"",E10-E9) -> 0 | M10: =IF(OR(F10="",F9=""),"",F10-F9) -> 0
A11: 46181 | B11: 1522845 | C11: 404800 | D11: 986000 | E11: 57000 | F11: 17000 | G11: =IF(COUNT(B11:F11)=0,"",SUM(B11:F11)) -> 2987645 | H11: 3000000 | I11: =IF(OR(B11="",B10=""),"",B11-B10) -> 0 | J11: =IF(OR(C11="",C10=""),"",C11-C10) -> 0 | K11: =IF(OR(D11="",D10=""),"",D11-D10) -> 0 | L11: =IF(OR(E11="",E10=""),"",E11-E10) -> 0 | M11: =IF(OR(F11="",F10=""),"",F11-F10) -> 0
A12: 46182 | B12: 1522793 | C12: 404790 | D12: 986300 | E12: 57100 | F12: 17000 | G12: =IF(COUNT(B12:F12)=0,"",SUM(B12:F12)) -> 2987983 | H12: 3000000 | I12: =IF(OR(B12="",B11=""),"",B12-B11) -> -52 | J12: =IF(OR(C12="",C11=""),"",C12-C11) -> -10 | K12: =IF(OR(D12="",D11=""),"",D12-D11) -> 300 | L12: =IF(OR(E12="",E11=""),"",E12-E11) -> 100 | M12: =IF(OR(F12="",F11=""),"",F12-F11) -> 0
A13: 46183 | B13: 1522602 | C13: 404829 | D13: 986191 | E13: 57100 | F13: 17000 | G13: =IF(COUNT(B13:F13)=0,"",SUM(B13:F13)) -> 2987722 | H13: 3000000 | I13: =IF(OR(B13="",B12=""),"",B13-B12) -> -191 | J13: =IF(OR(C13="",C12=""),"",C13-C12) -> 39 | K13: =IF(OR(D13="",D12=""),"",D13-D12) -> -109 | L13: =IF(OR(E13="",E12=""),"",E13-E12) -> 0 | M13: =IF(OR(F13="",F12=""),"",F13-F12) -> 0
A14: 46184 | B14: 1522602 | C14: 404829 | D14: 986191 | E14: 57100 | F14: 16984 | G14: =IF(COUNT(B14:F14)=0,"",SUM(B14:F14)) -> 2987706 | H14: 3000000 | I14: =IF(OR(B14="",B13=""),"",B14-B13) -> 0 | J14: =IF(OR(C14="",C13=""),"",C14-C13) -> 0 | K14: =IF(OR(D14="",D13=""),"",D14-D13) -> 0 | L14: =IF(OR(E14="",E13=""),"",E14-E13) -> 0 | M14: =IF(OR(F14="",F13=""),"",F14-F13) -> -16
A15: 46185 | B15: 1522521 | C15: 404821 | D15: 986139 | E15: 57115 | F15: 16987 | G15: =IF(COUNT(B15:F15)=0,"",SUM(B15:F15)) -> 2987583 | H15: 3000000 | I15: =IF(OR(B15="",B14=""),"",B15-B14) -> -81 | J15: =IF(OR(C15="",C14=""),"",C15-C14) -> -8 | K15: =IF(OR(D15="",D14=""),"",D15-D14) -> -52 | L15: =IF(OR(E15="",E14=""),"",E15-E14) -> 15 | M15: =IF(OR(F15="",F14=""),"",F15-F14) -> 3
A16: 46186 | B16: 1522444 | C16: 404823 | D16: 986089 | E16: 57134 | F16: 16991 | G16: =IF(COUNT(B16:F16)=0,"",SUM(B16:F16)) -> 2987481 | H16: 3000000 | I16: =IF(OR(B16="",B15=""),"",B16-B15) -> -77 | J16: =IF(OR(C16="",C15=""),"",C16-C15) -> 2 | K16: =IF(OR(D16="",D15=""),"",D16-D15) -> -50 | L16: =IF(OR(E16="",E15=""),"",E16-E15) -> 19 | M16: =IF(OR(F16="",F15=""),"",F16-F15) -> 4
A17: 46187 | B17: 1522336 | C17: 404865 | D17: 986005 | E17: 57149 | F17: 16992 | G17: =IF(COUNT(B17:F17)=0,"",SUM(B17:F17)) -> 2987347 | H17: 3000000 | I17: =IF(OR(B17="",B16=""),"",B17-B16) -> -108 | J17: =IF(OR(C17="",C16=""),"",C17-C16) -> 42 | K17: =IF(OR(D17="",D16=""),"",D17-D16) -> -84 | L17: =IF(OR(E17="",E16=""),"",E17-E16) -> 15 | M17: =IF(OR(F17="",F16=""),"",F17-F16) -> 1
... A88: 46258 | B88: 1538814 | C88: 408600 | D88: 983823 | E88: 58240 | F88: 17371 | G88: =IF(COUNT(B88:F88)=0,"",SUM(B88:F88)) -> 3006848 | H88: 3000000 | I88: =IF(OR(B88="",B87=""),"",B88-B87) -> 0 | J88: =IF(OR(C88="",C87=""),"",C88-C87) -> 0 | K88: =IF(OR(D88="",D87=""),"",D88-D87) -> 0 | L88: =IF(OR(E88="",E87=""),"",E88-E87) -> 0 | M88: =IF(OR(F88="",F87=""),"",F88-F87) -> 0
A89: 46259 | G89: =IF(COUNT(B89:F89)=0,"",SUM(B89:F89)) | H89: 3000000 | I89: =IF(OR(B89="",B88=""),"",B89-B88) | J89: =IF(OR(C89="",C88=""),"",C89-C88) | K89: =IF(OR(D89="",D88=""),"",D89-D88) | L89: =IF(OR(E89="",E88=""),"",E89-E88) | M89: =IF(OR(F89="",F88=""),"",F89-F88)
A90: 46260 | G90: =IF(COUNT(B90:F90)=0,"",SUM(B90:F90)) | H90: 3000000 | I90: =IF(OR(B90="",B89=""),"",B90-B89) | J90: =IF(OR(C90="",C89=""),"",C90-C89) | K90: =IF(OR(D90="",D89=""),"",D90-D89) | L90: =IF(OR(E90="",E89=""),"",E90-E89) | M90: =IF(OR(F90="",F89=""),"",F90-F89)
A91: 46261 | G91: =IF(COUNT(B91:F91)=0,"",SUM(B91:F91)) | H91: 3000000 | I91: =IF(OR(B91="",B90=""),"",B91-B90) | J91: =IF(OR(C91="",C90=""),"",C91-C90) | K91: =IF(OR(D91="",D90=""),"",D91-D90) | L91: =IF(OR(E91="",E90=""),"",E91-E90) | M91: =IF(OR(F91="",F90=""),"",F91-F90)
A92: 46262 | G92: =IF(COUNT(B92:F92)=0,"",SUM(B92:F92)) | H92: 3000000 | I92: =IF(OR(B92="",B91=""),"",B92-B91) | J92: =IF(OR(C92="",C91=""),"",C92-C91) | K92: =IF(OR(D92="",D91=""),"",D92-D91) | L92: =IF(OR(E92="",E91=""),"",E92-E91) | M92: =IF(OR(F92="",F91=""),"",F92-F91)
A93: 46263 | G93: =IF(COUNT(B93:F93)=0,"",SUM(B93:F93)) | H93: 3000000 | I93: =IF(OR(B93="",B92=""),"",B93-B92) | J93: =IF(OR(C93="",C92=""),"",C93-C92) | K93: =IF(OR(D93="",D92=""),"",D93-D92) | L93: =IF(OR(E93="",E92=""),"",E93-E92) | M93: =IF(OR(F93="",F92=""),"",F93-F92)
A94: 46264 | G94: =IF(COUNT(B94:F94)=0,"",SUM(B94:F94)) | H94: 3000000 | I94: =IF(OR(B94="",B93=""),"",B94-B93) | J94: =IF(OR(C94="",C93=""),"",C94-C93) | K94: =IF(OR(D94="",D93=""),"",D94-D93) | L94: =IF(OR(E94="",E93=""),"",E94-E93) | M94: =IF(OR(F94="",F93=""),"",F94-F93)
A95: 46265 | G95: =IF(COUNT(B95:F95)=0,"",SUM(B95:F95)) | H95: 3000000 | I95: =IF(OR(B95="",B94=""),"",B95-B94) | J95: =IF(OR(C95="",C94=""),"",C95-C94) | K95: =IF(OR(D95="",D94=""),"",D95-D94) | L95: =IF(OR(E95="",E94=""),"",E95-E94) | M95: =IF(OR(F95="",F94=""),"",F95-F94)
A96: 46266 | G96: =IF(COUNT(B96:F96)=0,"",SUM(B96:F96)) | H96: 3000000 | I96: =IF(OR(B96="",B95=""),"",B96-B95) | J96: =IF(OR(C96="",C95=""),"",C96-C95) | K96: =IF(OR(D96="",D95=""),"",D96-D95) | L96: =IF(OR(E96="",E95=""),"",E96-E95) | M96: =IF(OR(F96="",F95=""),"",F96-F95)
A97: 46267 | G97: =IF(COUNT(B97:F97)=0,"",SUM(B97:F97)) | H97: 3000000 | I97: =IF(OR(B97="",B96=""),"",B97-B96) | J97: =IF(OR(C97="",C96=""),"",C97-C96) | K97: =IF(OR(D97="",D96=""),"",D97-D96) | L97: =IF(OR(E97="",E96=""),"",E97-E96) | M97: =IF(OR(F97="",F96=""),"",F97-F96)
A98: 46268 | G98: =IF(COUNT(B98:F98)=0,"",SUM(B98:F98)) | H98: 3000000 | I98: =IF(OR(B98="",B97=""),"",B98-B97) | J98: =IF(OR(C98="",C97=""),"",C98-C97) | K98: =IF(OR(D98="",D97=""),"",D98-D97) | L98: =IF(OR(E98="",E97=""),"",E98-E97) | M98: =IF(OR(F98="",F97=""),"",F98-F97)
A99: 46269 | G99: =IF(COUNT(B99:F99)=0,"",SUM(B99:F99)) | H99: 3000000 | I99: =IF(OR(B99="",B98=""),"",B99-B98) | J99: =IF(OR(C99="",C98=""),"",C99-C98) | K99: =IF(OR(D99="",D98=""),"",D99-D98) | L99: =IF(OR(E99="",E98=""),"",E99-E98) | M99: =IF(OR(F99="",F98=""),"",F99-F98)
A100: 46270 | G100: =IF(COUNT(B100:F100)=0,"",SUM(B100:F100)) | H100: 3000000 | I100: =IF(OR(B100="",B99=""),"",B100-B99) | J100: =IF(OR(C100="",C99=""),"",C100-C99) | K100: =IF(OR(D100="",D99=""),"",D100-D99) | L100: =IF(OR(E100="",E99=""),"",E100-E99) | M100: =IF(OR(F100="",F99=""),"",F100-F99)
... A217: 46387 | G217: =IF(COUNT(B217:F217)=0,"",SUM(B217:F217)) | H217: 3000000 | I217: =IF(OR(B217="",B216=""),"",B217-B216) | J217: =IF(OR(C217="",C216=""),"",C217-C216) | K217: =IF(OR(D217="",D216=""),"",D217-D216) | L217: =IF(OR(E217="",E216=""),"",E217-E216) | M217: =IF(OR(F217="",F216=""),"",F217-F216)

Sheet Meta 3M
A1: META · 4.000.000 DE SEGUIDORES
A4: Meta de seguidores | B4: 4000000
A5: Total atual (último dia) | B5: =LOOKUP(9.99E+307,'Log Diário'!G5:G217) -> 3006848
A6: Data do último registro | B6: {=INDEX('Log Diário'!A5:A217,MATCH(9.99E+307,'Log Diário'!G5:G217))} -> 46258
A7: % da meta atingido | B7: =B5/B4 -> 0.751712
A8: Quanto falta para 3M | B8: =B4-B5 -> 993152
A9: Ganho da última semana (7d) | B9: {=B5-INDEX('Log Diário'!G5:G217,MATCH(9.99E+307,'Log Diário'!G5:G217)-7)} -> 3556
A10: Ritmo semanal médio (desde 02/06) | B10: =(B5-'Log Diário'!G5)/((B6-'Log Diário'!A5)/7) -> 1642.9759
A11: Semanas restantes (ritmo última semana) | B11: =IF(B9<=0,"—",B8/B9) -> 279.28909
A12: Data prevista 3M (ritmo última semana) | B12: =IF(B9<=0,"—",B6+B11*7) -> 48213.024
A13: Data prevista 3M (ritmo médio) | B13: =IF(B10<=0,"—",B6+(B8/B10)*7) -> 50489.385
A15: Célula amarela = editável (meta). Todo o resto calcula sozinho.
A17: SEMANA A SEMANA · RESULTADO vs META
A18: Semana (fim) | B18: Total no fim da semana | C18: Meta (3M) | D18: Ganho na semana | E18: % da meta | F18: Falta para 3M
A19: 46182 | B19: {=IFERROR(IF(INDEX('Log Diário'!G5:G217,MATCH(A19,'Log Diário'!A5:A217,0))="","",INDEX('Log Diário'!G5:G217,MATCH(A19,'Log Diário'!A5:A217,0))),"")} -> 2987983 | C19: 3000000 | D19: {=IFERROR(IF(OR(B19="",INDEX('Log Diário'!G5:G217,MATCH(A19,'Log Diário'!A5:A217,0)-7)=""),"",B19-INDEX('Log Diário'!G5:G217,MATCH(A19,'Log Diário'!A5:A217,0)-7)),"")} -> 616 | E19: =IF(B19="","",B19/$B$4) -> 0.74699575 | F19: =IF(B19="","",$B$4-B19) -> 1012017
A20: 46189 | B20: {=IFERROR(IF(INDEX('Log Diário'!G5:G217,MATCH(A20,'Log Diário'!A5:A217,0))="","",INDEX('Log Diário'!G5:G217,MATCH(A20,'Log Diário'!A5:A217,0))),"")} -> 2986975 | C20: 3000000 | D20: {=IFERROR(IF(OR(B20="",INDEX('Log Diário'!G5:G217,MATCH(A20,'Log Diário'!A5:A217,0)-7)=""),"",B20-INDEX('Log Diário'!G5:G217,MATCH(A20,'Log Diário'!A5:A217,0)-7)),"")} -> -1008 | E20: =IF(B20="","",B20/$B$4) -> 0.74674375 | F20: =IF(B20="","",$B$4-B20) -> 1013025
A21: 46196 | B21: {=IFERROR(IF(INDEX('Log Diário'!G5:G217,MATCH(A21,'Log Diário'!A5:A217,0))="","",INDEX('Log Diário'!G5:G217,MATCH(A21,'Log Diário'!A5:A217,0))),"")} -> 2987294 | C21: 3000000 | D21: {=IFERROR(IF(OR(B21="",INDEX('Log Diário'!G5:G217,MATCH(A21,'Log Diário'!A5:A217,0)-7)=""),"",B21-INDEX('Log Diário'!G5:G217,MATCH(A21,'Log Diário'!A5:A217,0)-7)),"")} -> 319 | E21: =IF(B21="","",B21/$B$4) -> 0.7468235 | F21: =IF(B21="","",$B$4-B21) -> 1012706
A22: 46203 | B22: {=IFERROR(IF(INDEX('Log Diário'!G5:G217,MATCH(A22,'Log Diário'!A5:A217,0))="","",INDEX('Log Diário'!G5:G217,MATCH(A22,'Log Diário'!A5:A217,0))),"")} -> 2985543 | C22: 3000000 | D22: {=IFERROR(IF(OR(B22="",INDEX('Log Diário'!G5:G217,MATCH(A22,'Log Diário'!A5:A217,0)-7)=""),"",B22-INDEX('Log Diário'!G5:G217,MATCH(A22,'Log Diário'!A5:A217,0)-7)),"")} -> -1751 | E22: =IF(B22="","",B22/$B$4) -> 0.74638575 | F22: =IF(B22="","",$B$4-B22) -> 1014457
A23: 46210 | B23: {=IFERROR(IF(INDEX('Log Diário'!G5:G217,MATCH(A23,'Log Diário'!A5:A217,0))="","",INDEX('Log Diário'!G5:G217,MATCH(A23,'Log Diário'!A5:A217,0))),"")} -> 2986573 | C23: 3000000 | D23: {=IFERROR(IF(OR(B23="",INDEX('Log Diário'!G5:G217,MATCH(A23,'Log Diário'!A5:A217,0)-7)=""),"",B23-INDEX('Log Diário'!G5:G217,MATCH(A23,'Log Diário'!A5:A217,0)-7)),"")} -> 1030 | E23: =IF(B23="","",B23/$B$4) -> 0.74664325 | F23: =IF(B23="","",$B$4-B23) -> 1013427
A24: 46217 | B24: {=IFERROR(IF(INDEX('Log Diário'!G5:G217,MATCH(A24,'Log Diário'!A5:A217,0))="","",INDEX('Log Diário'!G5:G217,MATCH(A24,'Log Diário'!A5:A217,0))),"")} -> 2988918 | C24: 3000000 | D24: {=IFERROR(IF(OR(B24="",INDEX('Log Diário'!G5:G217,MATCH(A24,'Log Diário'!A5:A217,0)-7)=""),"",B24-INDEX('Log Diário'!G5:G217,MATCH(A24,'Log Diário'!A5:A217,0)-7)),"")} -> 2345 | E24: =IF(B24="","",B24/$B$4) -> 0.7472295 | F24: =IF(B24="","",$B$4-B24) -> 1011082
A25: 46224 | B25: {=IFERROR(IF(INDEX('Log Diário'!G5:G217,MATCH(A25,'Log Diário'!A5:A217,0))="","",INDEX('Log Diário'!G5:G217,MATCH(A25,'Log Diário'!A5:A217,0))),"")} -> 2991543 | C25: 3000000 | D25: {=IFERROR(IF(OR(B25="",INDEX('Log Diário'!G5:G217,MATCH(A25,'Log Diário'!A5:A217,0)-7)=""),"",B25-INDEX('Log Diário'!G5:G217,MATCH(A25,'Log Diário'!A5:A217,0)-7)),"")} -> 2625 | E25: =IF(B25="","",B25/$B$4) -> 0.74788575 | F25: =IF(B25="","",$B$4-B25) -> 1008457
A26: 46231 | B26: {=IFERROR(IF(INDEX('Log Diário'!G5:G217,MATCH(A26,'Log Diário'!A5:A217,0))="","",INDEX('Log Diário'!G5:G217,MATCH(A26,'Log Diário'!A5:A217,0))),"")} -> 2991543 | C26: 3000000 | D26: {=IFERROR(IF(OR(B26="",INDEX('Log Diário'!G5:G217,MATCH(A26,'Log Diário'!A5:A217,0)-7)=""),"",B26-INDEX('Log Diário'!G5:G217,MATCH(A26,'Log Diário'!A5:A217,0)-7)),"")} -> 0 | E26: =IF(B26="","",B26/$B$4) -> 0.74788575 | F26: =IF(B26="","",$B$4-B26) -> 1008457
A27: 46238 | B27: {=IFERROR(IF(INDEX('Log Diário'!G5:G217,MATCH(A27,'Log Diário'!A5:A217,0))="","",INDEX('Log Diário'!G5:G217,MATCH(A27,'Log Diário'!A5:A217,0))),"")} -> 2995120 | C27: 3000000 | D27: {=IFERROR(IF(OR(B27="",INDEX('Log Diário'!G5:G217,MATCH(A27,'Log Diário'!A5:A217,0)-7)=""),"",B27-INDEX('Log Diário'!G5:G217,MATCH(A27,'Log Diário'!A5:A217,0)-7)),"")} -> 3577 | E27: =IF(B27="","",B27/$B$4) -> 0.74878 | F27: =IF(B27="","",$B$4-B27) -> 1004880
A28: 46245 | B28: {=IFERROR(IF(INDEX('Log Diário'!G5:G217,MATCH(A28,'Log Diário'!A5:A217,0))="","",INDEX('Log Diário'!G5:G217,MATCH(A28,'Log Diário'!A5:A217,0))),"")} -> 2998444 | C28: 3000000 | D28: {=IFERROR(IF(OR(B28="",INDEX('Log Diário'!G5:G217,MATCH(A28,'Log Diário'!A5:A217,0)-7)=""),"",B28-INDEX('Log Diário'!G5:G217,MATCH(A28,'Log Diário'!A5:A217,0)-7)),"")} -> 3324 | E28: =IF(B28="","",B28/$B$4) -> 0.749611 | F28: =IF(B28="","",$B$4-B28) -> 1001556
A29: 46251 | B29: {=IFERROR(IF(INDEX('Log Diário'!G5:G217,MATCH(A29,'Log Diário'!A5:A217,0))="","",INDEX('Log Diário'!G5:G217,MATCH(A29,'Log Diário'!A5:A217,0))),"")} -> 3003292 | C29: 4000000 | D29: {=IFERROR(IF(OR(B29="",INDEX('Log Diário'!G5:G217,MATCH(A29,'Log Diário'!A5:A217,0)-7)=""),"",B29-INDEX('Log Diário'!G5:G217,MATCH(A29,'Log Diário'!A5:A217,0)-7)),"")} -> 4848 | E29: =IF(B29="","",B29/$B$4) -> 0.750823 | F29: =IF(B29="","",$B$4-B29) -> 996708
A30: 46259 | B30: {=IFERROR(IF(INDEX('Log Diário'!G5:G217,MATCH(A30,'Log Diário'!A5:A217,0))="","",INDEX('Log Diário'!G5:G217,MATCH(A30,'Log Diário'!A5:A217,0))),"")} | C30: 4000000 | D30: {=IFERROR(IF(OR(B30="",INDEX('Log Diário'!G5:G217,MATCH(A30,'Log Diário'!A5:A217,0)-7)=""),"",B30-INDEX('Log Diário'!G5:G217,MATCH(A30,'Log Diário'!A5:A217,0)-7)),"")} | E30: =IF(B30="","",B30/$B$4) | F30: =IF(B30="","",$B$4-B30)
A31: 46266 | B31: {=IFERROR(IF(INDEX('Log Diário'!G5:G217,MATCH(A31,'Log Diário'!A5:A217,0))="","",INDEX('Log Diário'!G5:G217,MATCH(A31,'Log Diário'!A5:A217,0))),"")} | C31: 4000000 | D31: {=IFERROR(IF(OR(B31="",INDEX('Log Diário'!G5:G217,MATCH(A31,'Log Diário'!A5:A217,0)-7)=""),"",B31-INDEX('Log Diário'!G5:G217,MATCH(A31,'Log Diário'!A5:A217,0)-7)),"")} | E31: =IF(B31="","",B31/$B$4) | F31: =IF(B31="","",$B$4-B31)
A32: 46273 | B32: {=IFERROR(IF(INDEX('Log Diário'!G5:G217,MATCH(A32,'Log Diário'!A5:A217,0))="","",INDEX('Log Diário'!G5:G217,MATCH(A32,'Log Diário'!A5:A217,0))),"")} | C32: 4000000 | D32: {=IFERROR(IF(OR(B32="",INDEX('Log Diário'!G5:G217,MATCH(A32,'Log Diário'!A5:A217,0)-7)=""),"",B32-INDEX('Log Diário'!G5:G217,MATCH(A32,'Log Diário'!A5:A217,0)-7)),"")} | E32: =IF(B32="","",B32/$B$4) | F32: =IF(B32="","",$B$4-B32)
A33: 46280 | B33: {=IFERROR(IF(INDEX('Log Diário'!G5:G217,MATCH(A33,'Log Diário'!A5:A217,0))="","",INDEX('Log Diário'!G5:G217,MATCH(A33,'Log Diário'!A5:A217,0))),"")} | C33: 4000000 | D33: {=IFERROR(IF(OR(B33="",INDEX('Log Diário'!G5:G217,MATCH(A33,'Log Diário'!A5:A217,0)-7)=""),"",B33-INDEX('Log Diário'!G5:G217,MATCH(A33,'Log Diário'!A5:A217,0)-7)),"")} | E33: =IF(B33="","",B33/$B$4) | F33: =IF(B33="","",$B$4-B33)
A34: 46287 | B34: {=IFERROR(IF(INDEX('Log Diário'!G5:G217,MATCH(A34,'Log Diário'!A5:A217,0))="","",INDEX('Log Diário'!G5:G217,MATCH(A34,'Log Diário'!A5:A217,0))),"")} | C34: 4000000 | D34: {=IFERROR(IF(OR(B34="",INDEX('Log Diário'!G5:G217,MATCH(A34,'Log Diário'!A5:A217,0)-7)=""),"",B34-INDEX('Log Diário'!G5:G217,MATCH(A34,'Log Diário'!A5:A217,0)-7)),"")} | E34: =IF(B34="","",B34/$B$4) | F34: =IF(B34="","",$B$4-B34)
A35: 46294 | B35: {=IFERROR(IF(INDEX('Log Diário'!G5:G217,MATCH(A35,'Log Diário'!A5:A217,0))="","",INDEX('Log Diário'!G5:G217,MATCH(A35,'Log Diário'!A5:A217,0))),"")} | C35: 4000000 | D35: {=IFERROR(IF(OR(B35="",INDEX('Log Diário'!G5:G217,MATCH(A35,'Log Diário'!A5:A217,0)-7)=""),"",B35-INDEX('Log Diário'!G5:G217,MATCH(A35,'Log Diário'!A5:A217,0)-7)),"")} | E35: =IF(B35="","",B35/$B$4) | F35: =IF(B35="","",$B$4-B35)
A36: 46301 | B36: {=IFERROR(IF(INDEX('Log Diário'!G5:G217,MATCH(A36,'Log Diário'!A5:A217,0))="","",INDEX('Log Diário'!G5:G217,MATCH(A36,'Log Diário'!A5:A217,0))),"")} | C36: 4000000 | D36: {=IFERROR(IF(OR(B36="",INDEX('Log Diário'!G5:G217,MATCH(A36,'Log Diário'!A5:A217,0)-7)=""),"",B36-INDEX('Log Diário'!G5:G217,MATCH(A36,'Log Diário'!A5:A217,0)-7)),"")} | E36: =IF(B36="","",B36/$B$4) | F36: =IF(B36="","",$B$4-B36)
A37: 46308 | B37: {=IFERROR(IF(INDEX('Log Diário'!G5:G217,MATCH(A37,'Log Diário'!A5:A217,0))="","",INDEX('Log Diário'!G5:G217,MATCH(A37,'Log Diário'!A5:A217,0))),"")} | C37: 4000000 | D37: {=IFERROR(IF(OR(B37="",INDEX('Log Diário'!G5:G217,MATCH(A37,'Log Diário'!A5:A217,0)-7)=""),"",B37-INDEX('Log Diário'!G5:G217,MATCH(A37,'Log Diário'!A5:A217,0)-7)),"")} | E37: =IF(B37="","",B37/$B$4) | F37: =IF(B37="","",$B$4-B37)
A38: 46315 | B38: {=IFERROR(IF(INDEX('Log Diário'!G5:G217,MATCH(A38,'Log Diário'!A5:A217,0))="","",INDEX('Log Diário'!G5:G217,MATCH(A38,'Log Diário'!A5:A217,0))),"")} | C38: 4000000 | D38: {=IFERROR(IF(OR(B38="",INDEX('Log Diário'!G5:G217,MATCH(A38,'Log Diário'!A5:A217,0)-7)=""),"",B38-INDEX('Log Diário'!G5:G217,MATCH(A38,'Log Diário'!A5:A217,0)-7)),"")} | E38: =IF(B38="","",B38/$B$4) | F38: =IF(B38="","",$B$4-B38)
A39: 46322 | B39: {=IFERROR(IF(INDEX('Log Diário'!G5:G217,MATCH(A39,'Log Diário'!A5:A217,0))="","",INDEX('Log Diário'!G5:G217,MATCH(A39,'Log Diário'!A5:A217,0))),"")} | C39: 4000000 | D39: {=IFERROR(IF(OR(B39="",INDEX('Log Diário'!G5:G217,MATCH(A39,'Log Diário'!A5:A217,0)-7)=""),"",B39-INDEX('Log Diário'!G5:G217,MATCH(A39,'Log Diário'!A5:A217,0)-7)),"")} | E39: =IF(B39="","",B39/$B$4) | F39: =IF(B39="","",$B$4-B39)
A40: 46329 | B40: {=IFERROR(IF(INDEX('Log Diário'!G5:G217,MATCH(A40,'Log Diário'!A5:A217,0))="","",INDEX('Log Diário'!G5:G217,MATCH(A40,'Log Diário'!A5:A217,0))),"")} | C40: 4000000 | D40: {=IFERROR(IF(OR(B40="",INDEX('Log Diário'!G5:G217,MATCH(A40,'Log Diário'!A5:A217,0)-7)=""),"",B40-INDEX('Log Diário'!G5:G217,MATCH(A40,'Log Diário'!A5:A217,0)-7)),"")} | E40: =IF(B40="","",B40/$B$4) | F40: =IF(B40="","",$B$4-B40)
A41: 46336 | B41: {=IFERROR(IF(INDEX('Log Diário'!G5:G217,MATCH(A41,'Log Diário'!A5:A217,0))="","",INDEX('Log Diário'!G5:G217,MATCH(A41,'Log Diário'!A5:A217,0))),"")} | C41: 4000000 | D41: {=IFERROR(IF(OR(B41="",INDEX('Log Diário'!G5:G217,MATCH(A41,'Log Diário'!A5:A217,0)-7)=""),"",B41-INDEX('Log Diário'!G5:G217,MATCH(A41,'Log Diário'!A5:A217,0)-7)),"")} | E41: =IF(B41="","",B41/$B$4) | F41: =IF(B41="","",$B$4-B41)
A42: 46343 | B42: {=IFERROR(IF(INDEX('Log Diário'!G5:G217,MATCH(A42,'Log Diário'!A5:A217,0))="","",INDEX('Log Diário'!G5:G217,MATCH(A42,'Log Diário'!A5:A217,0))),"")} | C42: 4000000 | D42: {=IFERROR(IF(OR(B42="",INDEX('Log Diário'!G5:G217,MATCH(A42,'Log Diário'!A5:A217,0)-7)=""),"",B42-INDEX('Log Diário'!G5:G217,MATCH(A42,'Log Diário'!A5:A217,0)-7)),"")} | E42: =IF(B42="","",B42/$B$4) | F42: =IF(B42="","",$B$4-B42)
A43: 46350 | B43: {=IFERROR(IF(INDEX('Log Diário'!G5:G217,MATCH(A43,'Log Diário'!A5:A217,0))="","",INDEX('Log Diário'!G5:G217,MATCH(A43,'Log Diário'!A5:A217,0))),"")} | C43: 4000000 | D43: {=IFERROR(IF(OR(B43="",INDEX('Log Diário'!G5:G217,MATCH(A43,'Log Diário'!A5:A217,0)-7)=""),"",B43-INDEX('Log Diário'!G5:G217,MATCH(A43,'Log Diário'!A5:A217,0)-7)),"")} | E43: =IF(B43="","",B43/$B$4) | F43: =IF(B43="","",$B$4-B43)
A44: 46357 | B44: {=IFERROR(IF(INDEX('Log Diário'!G5:G217,MATCH(A44,'Log Diário'!A5:A217,0))="","",INDEX('Log Diário'!G5:G217,MATCH(A44,'Log Diário'!A5:A217,0))),"")} | C44: 4000000 | D44: {=IFERROR(IF(OR(B44="",INDEX('Log Diário'!G5:G217,MATCH(A44,'Log Diário'!A5:A217,0)-7)=""),"",B44-INDEX('Log Diário'!G5:G217,MATCH(A44,'Log Diário'!A5:A217,0)-7)),"")} | E44: =IF(B44="","",B44/$B$4) | F44: =IF(B44="","",$B$4-B44)
...

Sheet Dashboard
A1: DASHBOARD · CRESCIMENTO vs META 3M
A3: RESUMO POR REDE
A4: Rede | B4: Atual | C4: Início (02/06) | D4: Crescimento | E4: % Crescimento | F4: Meta proporcional
A5: Instagram | B5: =LOOKUP(9.99E+307,'Log Diário'!B5:B217) -> 1538814 | C5: ='Log Diário'!B5 -> 1521064 | D5: =B5-C5 -> 17750 | E5: =IF(C5=0,"",D5/C5) -> 0.011669463 | F5: =$H$5*(B5/$B$10) -> 2047079.2 | H5: 4000000
A6: TikTok | B6: =LOOKUP(9.99E+307,'Log Diário'!C5:C217) -> 408600 | C6: ='Log Diário'!C5 -> 404326 | D6: =B6-C6 -> 4274 | E6: =IF(C6=0,"",D6/C6) -> 0.010570678 | F6: =$H$5*(B6/$B$10) -> 543559.24
A7: Facebook | B7: =LOOKUP(9.99E+307,'Log Diário'!D5:D217) -> 983823 | C7: ='Log Diário'!D5 -> 988295 | D7: =B7-C7 -> -4472 | E7: =IF(C7=0,"",D7/C7) -> -0.0045249647 | F7: =$H$5*(B7/$B$10) -> 1308776.5
A8: YouTube | B8: =LOOKUP(9.99E+307,'Log Diário'!E5:E217) -> 58240 | C8: ='Log Diário'!E5 -> 56858 | D8: =B8-C8 -> 1382 | E8: =IF(C8=0,"",D8/C8) -> 0.024306166 | F8: =$H$5*(B8/$B$10) -> 77476.48
A9: LinkedIn | B9: =LOOKUP(9.99E+307,'Log Diário'!F5:F217) -> 17371 | C9: ='Log Diário'!F5 -> 16824 | D9: =B9-C9 -> 547 | E9: =IF(C9=0,"",D9/C9) -> 0.032513077 | F9: =$H$5*(B9/$B$10) -> 23108.584
A10: TOTAL | B10: =SUM(B5:B9) -> 3006848 | C10: =SUM(C5:C9) -> 2987367 | D10: =B10-C10 -> 19481 | E10: =D10/C10 -> 0.0065211271 | F10: =H5 -> 4000000
A52: REDE vs META PROPORCIONAL
A53: Rede | B53: Atual | C53: Meta proporcional
A54: Instagram | B54: =B5 -> 1538814 | C54: =F5 -> 2047079.2
A55: TikTok | B55: =B6 -> 408600 | C55: =F6 -> 543559.24
A56: Facebook | B56: =B7 -> 983823 | C56: =F7 -> 1308776.5
A57: YouTube | B57: =B8 -> 58240 | C57: =F8 -> 77476.48
A58: LinkedIn | B58: =B9 -> 17371 | C58: =F9 -> 23108.584
